/opt/homebrew/Cellar/python@3.13/3.13.2/Frameworks/Python.framework/Versions/3.13/Resources/Python.app/Contents/MacOS/Python: can't open file '/Users/nirajtamang/Documents/Projects/ Learning Back & ML/Phase 1/Week 1/Backend/app.py': [Errno 2] No such file or directory
 * Serving Flask app 'First_project'
 * Debug mode: on
[31m[1mWARNING: This is a development server. Do not use it in a production deployment. Use a production WSGI server instead.[0m
 * Running on http://127.0.0.1:3737
[33mPress CTRL+C to quit[0m
 * Restarting with stat
 * Debugger is active!
 * Debugger PIN: 920-026-263
Traceback (most recent call last):
  File "/Users/nirajtamang/Documents/Projects/ Learning Back & ML/Phase 1/Week 1/Backend/First_project.py", line 30, in <module>
    naya.run(port= 3737,debug=True)
    ~~~~~~~~^^^^^^^^^^^^^^^^^^^^^^^
  File "/Users/nirajtamang/Documents/Projects/ Learning Back & ML/Phase 1/Week 1/Backend/venv/lib/python3.13/site-packages/flask/app.py", line 662, in run
    run_simple(t.cast(str, host), port, self, **options)
    ~~~~~~~~~~^^^^^^^^^^^^^^^^^^^^^^^^^^^^^^^^^^^^^^^^^^
  File "/Users/nirajtamang/Documents/Projects/ Learning Back & ML/Phase 1/Week 1/Backend/venv/lib/python3.13/site-packages/werkzeug/serving.py", line 1115, in run_simple
    run_with_reloader(
    ~~~~~~~~~~~~~~~~~^
        srv.serve_forever,
        ^^^^^^^^^^^^^^^^^^
    ...<3 lines>...
        reloader_type=reloader_type,
        ^^^^^^^^^^^^^^^^^^^^^^^^^^^^
    )
    ^
  File "/Users/nirajtamang/Documents/Projects/ Learning Back & ML/Phase 1/Week 1/Backend/venv/lib/python3.13/site-packages/werkzeug/_reloader.py", line 459, in run_with_reloader
    ensure_echo_on()
    ~~~~~~~~~~~~~~^^
  File "/Users/nirajtamang/Documents/Projects/ Learning Back & ML/Phase 1/Week 1/Backend/venv/lib/python3.13/site-packages/werkzeug/_reloader.py", line 439, in ensure_echo_on
    termios.tcsetattr(sys.stdin, termios.TCSANOW, attributes)
    ~~~~~~~~~~~~~~~~~^^^^^^^^^^^^^^^^^^^^^^^^^^^^^^^^^^^^^^^^
termios.error: (4, 'Interrupted system call')
Fatal Python error: init_sys_streams: can't initialize sys standard streams
Python runtime state: core initialized
OSError: [Errno 9] Bad file descriptor

Current thread 0x00000001f5cf7840 (most recent call first):
  <no Python frame>
